{
 "cells": [
  {
   "cell_type": "markdown",
   "metadata": {},
   "source": [
    "# **RUNNING SHELL COMMANDS USING PYTHON**"
   ]
  },
  {
   "cell_type": "code",
   "execution_count": 2,
   "metadata": {},
   "outputs": [],
   "source": [
    "import os\n",
    "\n",
    "try:\n",
    "    os.system('cmd /k \"date\"')\n",
    "except:\n",
    "    raise \"Couldn't execute command\""
   ]
  },
  {
   "cell_type": "code",
   "execution_count": 8,
   "metadata": {},
   "outputs": [
    {
     "name": "stdout",
     "output_type": "stream",
     "text": [
      " Volume in drive D is DATA\n",
      " Volume Serial Number is 2C12-72A4\n",
      "\n",
      " Directory of d:\\WORK\\PYTHON\\Projects\\NOVA_AI\\notebooks\n",
      "\n",
      "29-07-2024  18:44    <DIR>          .\n",
      "30-07-2024  12:28    <DIR>          ..\n",
      "30-07-2024  12:36             4,378 experiments.ipynb\n",
      "               1 File(s)          4,378 bytes\n",
      "               2 Dir(s)  909,407,084,544 bytes free\n",
      "\n"
     ]
    }
   ],
   "source": [
    "import subprocess\n",
    "\n",
    "# capture_output=True an argument of line below that has to be used without stdout=subprocess.PIPE\n",
    "p1 = subprocess.run(\"dir\", shell=True, stdout=subprocess.PIPE, text=True)\n",
    "#                                               ^ the file where output is redirected, we can use custom txt file or a log file to store this as well\n",
    "\n",
    "print(p1.stdout)"
   ]
  },
  {
   "cell_type": "code",
   "execution_count": 10,
   "metadata": {},
   "outputs": [],
   "source": [
    "with open(\"outputs/output.txt\", 'w') as f:\n",
    "    p1 = subprocess.run(\"dir\", shell=True, stdout=f, text=True)"
   ]
  },
  {
   "cell_type": "markdown",
   "metadata": {},
   "source": [
    "We have created an outputs folder and inside that we can see that we have a txt file with the name output.txt storing the result of the command that we just executed"
   ]
  },
  {
   "cell_type": "code",
   "execution_count": 13,
   "metadata": {},
   "outputs": [
    {
     "name": "stdout",
     "output_type": "stream",
     "text": [
      " Volume in drive D is DATA\n",
      " Volume Serial Number is 2C12-72A4\n",
      "\n",
      " Directory of d:\\WORK\\PYTHON\\Projects\\NOVA_AI\\notebooks\n",
      "\n",
      "30-07-2024  12:40    <DIR>          .\n",
      "30-07-2024  12:28    <DIR>          ..\n",
      "30-07-2024  12:41             2,411 experiments.ipynb\n",
      "30-07-2024  12:40    <DIR>          outputs\n",
      "               1 File(s)          2,411 bytes\n",
      "               3 Dir(s)  909,407,084,544 bytes free\n",
      "\n"
     ]
    }
   ],
   "source": [
    "p1 = subprocess.run(\"dir\", shell=True, capture_output=True, text=True)\n",
    "print(p1.stdout)"
   ]
  },
  {
   "cell_type": "markdown",
   "metadata": {},
   "source": [
    "What if the command fails, does python returns any traceback? NO"
   ]
  },
  {
   "cell_type": "markdown",
   "metadata": {},
   "source": [
    "why? One possible reason is that the error isn't generated by the python script but actually the command line, which just returns a non-zero return code, indicating that execution was unsuccessful"
   ]
  },
  {
   "cell_type": "code",
   "execution_count": 15,
   "metadata": {},
   "outputs": [
    {
     "data": {
      "text/plain": [
       "CompletedProcess(args='dire', returncode=1, stdout='', stderr=\"'dire' is not recognized as an internal or external command,\\noperable program or batch file.\\n\")"
      ]
     },
     "execution_count": 15,
     "metadata": {},
     "output_type": "execute_result"
    }
   ],
   "source": [
    "subprocess.run(\"dire\", shell=True, capture_output=True, text=True)"
   ]
  },
  {
   "cell_type": "markdown",
   "metadata": {},
   "source": [
    "see the return code is 1, can we handle this in python??? for sure"
   ]
  },
  {
   "cell_type": "code",
   "execution_count": 23,
   "metadata": {},
   "outputs": [
    {
     "name": "stdout",
     "output_type": "stream",
     "text": [
      "COULDN'T EXECUTE COMMAND\n"
     ]
    }
   ],
   "source": [
    "p1 = subprocess.run(\"dire\", shell=True, capture_output=True, text=True)\n",
    "\n",
    "if p1.returncode != 0:\n",
    "    print(\"COULDN'T EXECUTE COMMAND\")\n",
    "else:\n",
    "    print(p1.stdout)"
   ]
  },
  {
   "cell_type": "markdown",
   "metadata": {},
   "source": [
    "Now we have handled that exception as well, but what is the cause of the error???? we can show that too"
   ]
  },
  {
   "cell_type": "code",
   "execution_count": 24,
   "metadata": {},
   "outputs": [
    {
     "name": "stdout",
     "output_type": "stream",
     "text": [
      "COULDN'T EXECUTE COMMAND\n",
      "'dire' is not recognized as an internal or external command,\n",
      "operable program or batch file.\n",
      "\n"
     ]
    }
   ],
   "source": [
    "p1 = subprocess.run(\"dire\", shell=True, capture_output=True, text=True)\n",
    "\n",
    "if p1.returncode != 0:\n",
    "    print(\"COULDN'T EXECUTE COMMAND\")\n",
    "    print(p1.stderr)\n",
    "else:\n",
    "    print(p1.stdout)"
   ]
  },
  {
   "cell_type": "markdown",
   "metadata": {},
   "source": [
    "Now we have returned the error cause as well"
   ]
  },
  {
   "cell_type": "markdown",
   "metadata": {},
   "source": [
    "But can we make python handle this error and throw an inbuilt traceback???\n",
    "for sure"
   ]
  },
  {
   "cell_type": "code",
   "execution_count": 25,
   "metadata": {},
   "outputs": [
    {
     "ename": "CalledProcessError",
     "evalue": "Command 'dire' returned non-zero exit status 1.",
     "output_type": "error",
     "traceback": [
      "\u001b[1;31m---------------------------------------------------------------------------\u001b[0m",
      "\u001b[1;31mCalledProcessError\u001b[0m                        Traceback (most recent call last)",
      "Cell \u001b[1;32mIn[25], line 1\u001b[0m\n\u001b[1;32m----> 1\u001b[0m p1 \u001b[38;5;241m=\u001b[39m \u001b[43msubprocess\u001b[49m\u001b[38;5;241;43m.\u001b[39;49m\u001b[43mrun\u001b[49m\u001b[43m(\u001b[49m\u001b[38;5;124;43m\"\u001b[39;49m\u001b[38;5;124;43mdire\u001b[39;49m\u001b[38;5;124;43m\"\u001b[39;49m\u001b[43m,\u001b[49m\u001b[43m \u001b[49m\u001b[43mshell\u001b[49m\u001b[38;5;241;43m=\u001b[39;49m\u001b[38;5;28;43;01mTrue\u001b[39;49;00m\u001b[43m,\u001b[49m\u001b[43m \u001b[49m\u001b[43mcapture_output\u001b[49m\u001b[38;5;241;43m=\u001b[39;49m\u001b[38;5;28;43;01mTrue\u001b[39;49;00m\u001b[43m,\u001b[49m\u001b[43m \u001b[49m\u001b[43mtext\u001b[49m\u001b[38;5;241;43m=\u001b[39;49m\u001b[38;5;28;43;01mTrue\u001b[39;49;00m\u001b[43m,\u001b[49m\u001b[43m \u001b[49m\u001b[43mcheck\u001b[49m\u001b[38;5;241;43m=\u001b[39;49m\u001b[38;5;28;43;01mTrue\u001b[39;49;00m\u001b[43m)\u001b[49m\n",
      "File \u001b[1;32mc:\\Users\\chinm\\AppData\\Local\\Programs\\Python\\Python312\\Lib\\subprocess.py:571\u001b[0m, in \u001b[0;36mrun\u001b[1;34m(input, capture_output, timeout, check, *popenargs, **kwargs)\u001b[0m\n\u001b[0;32m    569\u001b[0m     retcode \u001b[38;5;241m=\u001b[39m process\u001b[38;5;241m.\u001b[39mpoll()\n\u001b[0;32m    570\u001b[0m     \u001b[38;5;28;01mif\u001b[39;00m check \u001b[38;5;129;01mand\u001b[39;00m retcode:\n\u001b[1;32m--> 571\u001b[0m         \u001b[38;5;28;01mraise\u001b[39;00m CalledProcessError(retcode, process\u001b[38;5;241m.\u001b[39margs,\n\u001b[0;32m    572\u001b[0m                                  output\u001b[38;5;241m=\u001b[39mstdout, stderr\u001b[38;5;241m=\u001b[39mstderr)\n\u001b[0;32m    573\u001b[0m \u001b[38;5;28;01mreturn\u001b[39;00m CompletedProcess(process\u001b[38;5;241m.\u001b[39margs, retcode, stdout, stderr)\n",
      "\u001b[1;31mCalledProcessError\u001b[0m: Command 'dire' returned non-zero exit status 1."
     ]
    }
   ],
   "source": [
    "p1 = subprocess.run(\"dire\", shell=True, capture_output=True, text=True, check=True)"
   ]
  },
  {
   "cell_type": "markdown",
   "metadata": {},
   "source": [
    "Now python handled the exception and threw a CalledProcessError"
   ]
  },
  {
   "cell_type": "markdown",
   "metadata": {},
   "source": [
    "But what if we want to store the error in a log file? or ignore the error"
   ]
  },
  {
   "cell_type": "code",
   "execution_count": 26,
   "metadata": {},
   "outputs": [
    {
     "name": "stdout",
     "output_type": "stream",
     "text": [
      "None\n"
     ]
    }
   ],
   "source": [
    "p1 = subprocess.run(\"dire\", shell=True, stderr=subprocess.DEVNULL) #ignore the error and returns None\n",
    "print(p1.stdout)"
   ]
  },
  {
   "cell_type": "markdown",
   "metadata": {},
   "source": [
    "Or we can store it in a log file"
   ]
  },
  {
   "cell_type": "code",
   "execution_count": 27,
   "metadata": {},
   "outputs": [],
   "source": [
    "#p1 = subprocess.run(\"dire\", shell=True, stderr=\"\"\"file object here\"\"\")"
   ]
  },
  {
   "cell_type": "code",
   "execution_count": null,
   "metadata": {},
   "outputs": [],
   "source": []
  }
 ],
 "metadata": {
  "kernelspec": {
   "display_name": "Python 3",
   "language": "python",
   "name": "python3"
  },
  "language_info": {
   "codemirror_mode": {
    "name": "ipython",
    "version": 3
   },
   "file_extension": ".py",
   "mimetype": "text/x-python",
   "name": "python",
   "nbconvert_exporter": "python",
   "pygments_lexer": "ipython3",
   "version": "3.12.3"
  }
 },
 "nbformat": 4,
 "nbformat_minor": 2
}
